<?xml version="1.0"?>
<robot xmlns:xacro="http://www.ros.org/wiki/xacro" name="tx200">
  <link name="world"></link>
  <link
    name="robot_base_link">
    <inertial>
      <origin
        xyz="0.00026066 0.00094721 0.16721"
        rpy="0 0 0" />
      <mass
        value="63.755" />
      <inertia
        ixx="1.6712"
        ixy="-0.0046856"
        ixz="-4.7419E-05"
        iyy="1.6412"
        iyz="-0.015828"
        izz="2.0916" />
    </inertial>
    <visual>
      <origin
        xyz="0 0 0"
        rpy="0 0 0" />
      <geometry>
        <mesh
          filename="package://robot-arm/meshes/tx200/visual/base_link.STL" />
      </geometry>
      <material
        name="">
        <color
          rgba="1 0.50196 0 1" />
      </material>
    </visual>
    <collision>
      <origin
        xyz="0 0 0"
        rpy="0 0 0" />
      <geometry>
        <mesh
          filename="package://robot-arm/meshes/tx200/collision/base_link.STL" />
      </geometry>
    </collision>
  </link>
  <link
    name="shoulder_link">
    <inertial>
      <origin
        xyz="0.14856 -0.013564 0.25306"
        rpy="0 0 0" />
      <mass
        value="154.38" />
      <inertia
        ixx="5.8791"
        ixy="0.005498"
        ixz="-0.62699"
        iyy="8.2707"
        iyz="-0.09633"
        izz="8.1731" />
    </inertial>
    <visual>
      <origin
        xyz="0 0 0"
        rpy="0 0 0" />
      <geometry>
        <mesh
          filename="package://robot-arm/meshes/tx200/visual/shoulder_link.STL" />
      </geometry>
      <material
        name="">
        <color
          rgba="1 0.50196 0 1" />
      </material>
    </visual>
    <collision>
      <origin
        xyz="0 0 0"
        rpy="0 0 0" />
      <geometry>
        <mesh
          filename="package://robot-arm/meshes/tx200/collision/shoulder_link.STL" />
      </geometry>
    </collision>
  </link>

  <joint name="world_to_robot_base" type="fixed">
    <parent link="world" />
    <child link="robot_base_link" />
  </joint>
  <joint
    name="base_to_shoulder_joint"
    type="revolute">
    <origin
      xyz="0 0 0.347"
      rpy="0 0 0" />
    <parent
      link="robot_base_link" />
    <child
      link="shoulder_link" />
    <axis
      xyz="0 0 -1" />
    <limit
      lower="${shoulder_joint_lower_limit}"
      upper="${shoulder_joint_upper_limit}"
      effort="0"
      velocity="0" />
  </joint>
  <link
    name="arm_link">
    <inertial>
      <origin
        xyz="0.0044408 0.33383 -0.15881"
        rpy="0 0 0" />
      <mass
        value="120.7" />
      <inertia
        ixx="16.904"
        ixy="-0.082464"
        ixz="0.0042604"
        iyy="2.2595"
        iyz="0.19322"
        izz="17.972" />
    </inertial>
    <visual>
      <origin
        xyz="0 0 0"
        rpy="0 0 0" />
      <geometry>
        <mesh
          filename="package://robot-arm/meshes/tx200/visual/arm_link.STL" />
      </geometry>
      <material
        name="">
        <color
          rgba="1 0.50196 0 1" />
      </material>
    </visual>
    <collision>
      <origin
        xyz="0 0 0"
        rpy="0 0 0" />
      <geometry>
        <mesh
          filename="package://robot-arm/meshes/tx200/collision/arm_link.STL" />
      </geometry>
    </collision>
  </link>
  <joint
    name="shoulder_to_arm_joint"
    type="revolute">
    <origin
      xyz="0.25 0.239 0.301"
      rpy="1.5708 0 0" />
    <parent
      link="shoulder_link" />
    <child
      link="arm_link" />
    <axis
      xyz="0 0 -1" />
    <limit
      lower="${arm_joint_lower_limit}"
      upper="${arm_joint_upper_limit}"
      effort="0"
      velocity="0" />
  </joint>
  <link
    name="elbow_link">
    <inertial>
      <origin
        xyz="-0.02969 -0.042696 -0.23138"
        rpy="0 0 0" />
      <mass
        value="54.85" />
      <inertia
        ixx="1.5777"
        ixy="-0.22458"
        ixz="-0.060632"
        iyy="1.2712"
        iyz="-0.078975"
        izz="1.2875" />
    </inertial>
    <visual>
      <origin
        xyz="0 0 0"
        rpy="0 0 0" />
      <geometry>
        <mesh
          filename="package://robot-arm/meshes/tx200/visual/elbow_link.STL" />
      </geometry>
      <material
        name="">
        <color
          rgba="1 0.50196 0 1" />
      </material>
    </visual>
    <collision>
      <origin
        xyz="0 0 0"
        rpy="0 0 0" />
      <geometry>
        <mesh
          filename="package://robot-arm/meshes/tx200/collision/elbow_link.STL" />
      </geometry>
    </collision>
  </link>
  <joint
    name="arm_to_elbow_joint"
    type="revolute">
    <origin
      xyz="-0.0013914 0.95009 -0.04995"
      rpy="${pi} 0 ${pi/2}" />
    <parent
      link="arm_link" />
    <child
      link="elbow_link" />
    <axis
      xyz="0 0 -1" />
    <limit
      lower="${elbow_joint_lower_limit}"
      upper="${elbow_joint_upper_limit}"
      effort="0"
      velocity="0" />
  </joint>
  <link
    name="forearm_link">
    <inertial>
      <origin
        xyz="0.0051041 0.0017748 0.3241"
        rpy="0 0 0" />
      <mass
        value="32.604" />
      <inertia
        ixx="9.7"
        ixy="0.00055231"
        ixz="-0.03"
        iyy="9.57"
        iyz="0.14"
        izz="0.3536" />
    </inertial>
    <visual>
      <origin
        xyz="0 0 0"
        rpy="0 0 0" />
      <geometry>
        <mesh
          filename="package://robot-arm/meshes/tx200/visual/forearm_link.STL" />
      </geometry>
      <material
        name="">
        <color
          rgba="1 0.50196 0 1" />
      </material>
    </visual>
    <collision>
      <origin
        xyz="0 0 0"
        rpy="0 0 0" />
      <geometry>
        <mesh
          filename="package://robot-arm/meshes/tx200/collision/forearm_link.STL" />
      </geometry>
    </collision>
  </link>
  <joint
    name="elbow_to_forearm_joint"
    type="revolute">
    <origin
      xyz="0 0.17799 -0.2758"
      rpy="${-pi/2} ${-pi/2} 0" />
    <parent
      link="elbow_link" />
    <child
      link="forearm_link" />
    <axis
      xyz="0 0 -1" />
    <limit
      lower="${forearm_joint_lower_limit}"
      upper="${forearm_joint_upper_limit}"
      effort="0"
      velocity="0" />
  </joint>
  <link
    name="wrist_link">
    <inertial>
      <origin
        xyz="0.049261 2.4716E-05 -0.0025318"
        rpy="0 0 0" />
      <mass
        value="5.3091" />
      <inertia
        ixx="0.05"
        ixy="-6.8698E-06"
        ixz="0.00015324"
        iyy="0.02"
        iyz="3.9383E-06"
        izz="0.05" />
    </inertial>
    <visual>
      <origin
        xyz="0 0 0"
        rpy="0 0 0" />
      <geometry>
        <mesh
          filename="package://robot-arm/meshes/tx200/visual/wrist_link.STL" />
      </geometry>
      <material
        name="">
        <color
          rgba="1 0.50196 0 1" />
      </material>
    </visual>
    <collision>
      <origin
        xyz="0 0 0"
        rpy="0 0 0" />
      <geometry>
        <mesh
          filename="package://robot-arm/meshes/tx200/collision/wrist_link.STL" />
      </geometry>
    </collision>
  </link>
  <joint
    name="forearm_to_wrist_joint"
    type="revolute">
    <origin
      xyz="-0.00375 -8.7479E-05 0.62225"
      rpy="${pi} ${-pi/2} 0" />
    <parent
      link="forearm_link" />
    <child
      link="wrist_link" />
    <axis
      xyz="0 0 -1" />
    <limit
      lower="${wrist_joint_lower_limit}"
      upper="${wrist_joint_upper_limit}"
      effort="0"
      velocity="0" />
  </joint>
</robot>